<robot name="galileo_v1d6">
  <link name="base_link">
    <inertial>
      <origin xyz="0.0027831 -0.009841 -0.0002665" rpy="0 0 0" />
      <mass value="24.0427431" />
      <inertia ixx="0.1136788" iyy="0.3485644" izz="0.408405" ixy="0.0016372" ixz="0.0001502" iyz="3.6e-05" />
    </inertial>
    <visual>
      <origin xyz="0 0 0" rpy="0 0 0" />
      <geometry>
        <mesh filename="package://galileo_v1d6_description/meshes/TRUCK.STL" scale="1 1 1" />
      </geometry>
      <material name="">
        <color rgba="0.8 0.4 0 1" />
      </material>
    </visual>
    <collision>
      <origin xyz="0 0 -0.01" rpy="0 0 0" />
      <geometry>
        <box size="0.42 0.26 0.18" />
      </geometry>
    </collision>
    <!-- template_collision_placeholder -->
  </link>

  <link name="FL_hip">
    <inertial>
      <origin xyz="-0.0034539 0.0001471 -0.0009605" rpy="0 0 0" />
      <mass value="1.6459372" />
      <inertia ixx="0.0004144" iyy="0.000796" izz="0.0005767" ixy="1e-05" ixz="1.5e-06" iyz="-1.4e-06" />
    </inertial>
    <visual>
      <origin xyz="0 0 0" rpy="0 0 0" />
      <geometry>
        <mesh filename="package://galileo_v1d6_description/meshes/FL_HIP.STL" scale="1 1 1" />
      </geometry>
      <material name="">
        <color rgba="1 0.4 0.4 1" />
      </material>
    </visual>
    <!-- <collision>
      <origin xyz="0 0 0" rpy="0 0 0"/>
      <geometry>
        <mesh filename="package://galileo_v1d6_description/meshes/FL_HIP.STL" scale="1 1 1"/>
      </geometry>
    </collision> -->
    <!-- template_collision_placeholder -->
  </link>

  <joint name="FL_hip_joint" type="revolute">
    <origin xyz="0.279 0.067 0" rpy="0 0 0" />
    <parent link="base_link" />
    <child link="FL_hip" />
    <axis xyz="1 0 0" />
    <limit lower="-0.698132" upper="0.698132" effort="120" velocity="12.0" />
  </joint>

  <link name="FL_thigh">
    <inertial>
      <origin xyz="-0.0028001 -0.0368096 -0.0239021" rpy="0 0 0" />
      <mass value="2.2115554" />
      <inertia ixx="0.012133" iyy="0.0117725" izz="0.0019164" ixy="0.0002099" ixz="-0.000542" iyz="0.0020399" />
    </inertial>
    <visual>
      <origin xyz="0 0 0" rpy="0 0 0" />
      <geometry>
        <mesh filename="package://galileo_v1d6_description/meshes/FL_THIGH.STL" scale="1 1 1" />
      </geometry>
      <material name="">
        <color rgba="1 1 0.4 1" />
      </material>
    </visual>
    <collision>
      <origin xyz="-0.025 0 -0.15" rpy="0 0 0" />
      <geometry>
        <box size="0.05 0.02 0.18" />
      </geometry>
    </collision>
    <collision>
      <origin xyz="0 -0.065 0" rpy="1.57 1.57 0" />
      <geometry>
        <cylinder radius="0.06" length="0.08" />
      </geometry>
    </collision>
    <!-- template_collision_placeholder -->
  </link>

  <joint name="FL_thigh_joint" type="revolute">
    <origin xyz="0 0.1103 0" rpy="0 0 0" />
    <parent link="FL_hip" />
    <child link="FL_thigh" />
    <axis xyz="0 1 0" />
    <limit lower="-1.762783" upper="3.647738" effort="120" velocity="12.0" />
  </joint>

  <link name="FL_calf">
    <inertial>
      <origin xyz="0.006276 6e-05 -0.1458107" rpy="0 0 0" />
      <mass value="0.3248308" />
      <inertia ixx="0.0041942" iyy="0.0042423" izz="9.93e-05" ixy="0" ixz="-3e-07" iyz="0" />
    </inertial>
    <visual>
      <origin xyz="0 0 0" rpy="0 0 0" />
      <geometry>
        <mesh filename="package://galileo_v1d6_description/meshes/FL_CALF.STL" scale="1 1 1" />
      </geometry>
      <material name="">
        <color rgba="0.4 1 0.4 1" />
      </material>
    </visual>
    <collision>
      <origin xyz="0.015 0.0 -0.235" rpy="0 0.5 0" />
      <geometry>
        <box size="0.04 0.02 0.05" />
      </geometry>
    </collision>
    <collision>
      <origin xyz="0.0085 0.0 -0.092" rpy="0 -0.15 0" />
      <geometry>
        <box size="0.032 0.02 0.27" />
      </geometry>
    </collision>
    <!-- template_collision_placeholder -->
  </link>

  <joint name="FL_calf_joint" type="revolute">
    <origin xyz="0 0 -0.26" rpy="0 0 0" />
    <parent link="FL_thigh" />
    <child link="FL_calf" />
    <axis xyz="0 1 0" />
    <limit lower="-2.740167" upper="-0.383972" effort="120" velocity="12.0" />
  </joint>

  <link name="FL_foot">
    <inertial>
      <origin xyz="0 0 0" rpy="0 0 0" />
      <mass value="0.04" />
      <inertia ixx="9.6e-06" ixy="0" ixz="0" iyy="9.6e-06" iyz="0" izz="9.6e-06" />
    </inertial>
    <visual>
      <origin xyz="0 0 0" rpy="0 0 0" />
      <geometry>
        <sphere radius="0.026" />
      </geometry>
      <material name="">
        <color rgba="0 0.5 1 1" />
      </material>
    </visual>
    <collision>
      <origin xyz="0 0 0" rpy="0 0 0" />
      <geometry>
        <sphere radius="0.026" />
      </geometry>
    </collision>
    <!-- template_collision_placeholder -->
  </link>

  <joint name="FL_foot_joint" type="fixed" dont_collapse="true">
    <origin xyz="0 0 -0.26" rpy="0 0 0" />
    <parent link="FL_calf" />
    <child link="FL_foot" />
    <axis xyz="0 1 0" />
    <limit lower="0" upper="0" effort="0" velocity="0" />
  </joint>

  <link name="RL_hip">
    <inertial>
      <origin xyz="-0.0034539 0.0001471 -0.0009605" rpy="0 0 0" />
      <mass value="1.6459372" />
      <inertia ixx="0.0004144" iyy="0.000796" izz="0.0005767" ixy="-1e-05" ixz="-1.5e-06" iyz="-1.4e-06" />
    </inertial>
    <visual>
      <origin xyz="0 0 0" rpy="0 0 0" />
      <geometry>
        <mesh filename="package://galileo_v1d6_description/meshes/RL_HIP.STL" scale="1 1 1" />
      </geometry>
      <material name="">
        <color rgba="0.8 1.0 0.8 1" />
      </material>
    </visual>
    <!-- <collision>
      <origin xyz="0 0 0" rpy="0 0 0"/>
      <geometry>
        <mesh filename="package://galileo_v1d6_description/meshes/RL_HIP.STL" scale="1 1 1"/>
      </geometry>
    </collision> -->
    <!-- template_collision_placeholder -->
  </link>

  <joint name="RL_hip_joint" type="revolute">
    <origin xyz="-0.279 0.067 0" rpy="0 0 0" />
    <parent link="base_link" />
    <child link="RL_hip" />
    <axis xyz="1 0 0" />
    <limit lower="-0.698132" upper="0.698132" effort="120" velocity="12.0" />
  </joint>

  <link name="RL_thigh">
    <inertial>
      <origin xyz="-0.0028001 -0.0368096 -0.0239021" rpy="0 0 0" />
      <mass value="2.2115554" />
      <inertia ixx="0.012133" iyy="0.0117725" izz="0.0019164" ixy="0.0002099" ixz="-0.000542" iyz="0.0020399" />
    </inertial>
    <visual>
      <origin xyz="0 0 0" rpy="0 0 0" />
      <geometry>
        <mesh filename="package://galileo_v1d6_description/meshes/FL_THIGH.STL" scale="1 1 1" />
      </geometry>
      <material name="">
        <color rgba="1 0.5 1 1" />
      </material>
    </visual>
    <collision>
      <origin xyz="-0.025 0 -0.15" rpy="0 0 0" />
      <geometry>
        <box size="0.05 0.02 0.18" />
      </geometry>
    </collision>
    <collision>
      <origin xyz="0 -0.065 0" rpy="1.57 1.57 0" />
      <geometry>
        <cylinder radius="0.06" length="0.08" />
      </geometry>
    </collision>
    <!-- template_collision_placeholder -->
  </link>

  <joint name="RL_thigh_joint" type="revolute">
    <origin xyz="0 0.1103 0" rpy="0 0 0" />
    <parent link="RL_hip" />
    <child link="RL_thigh" />
    <axis xyz="0 1 0" />
    <limit lower="-1.762783" upper="3.647738" effort="120" velocity="12.0" />
  </joint>

  <link name="RL_calf">
    <inertial>
      <origin xyz="0.006276 6e-05 -0.1458107" rpy="0 0 0" />
      <mass value="0.3248308" />
      <inertia ixx="0.0041942" iyy="0.0042423" izz="9.93e-05" ixy="0" ixz="-3e-07" iyz="0" />
    </inertial>
    <visual>
      <origin xyz="0 0 0" rpy="0 0 0" />
      <geometry>
        <mesh filename="package://galileo_v1d6_description/meshes/FL_CALF.STL" scale="1 1 1" />
      </geometry>
      <material name="">
        <color rgba="1 0.4 0.4 1" />
      </material>
    </visual>
    <collision>
      <origin xyz="0.015 0.0 -0.235" rpy="0 0.5 0" />
      <geometry>
        <box size="0.04 0.02 0.05" />
      </geometry>
    </collision>
    <collision>
      <origin xyz="0.0085 0.0 -0.092" rpy="0 -0.15 0" />
      <geometry>
        <box size="0.032 0.02 0.27" />
      </geometry>
    </collision>
    <!-- template_collision_placeholder -->
  </link>

  <joint name="RL_calf_joint" type="revolute">
    <origin xyz="0 0 -0.26" rpy="0 0 0" />
    <parent link="RL_thigh" />
    <child link="RL_calf" />
    <axis xyz="0 1 0" />
    <limit lower="-2.740167" upper="-0.383972" effort="120" velocity="12.0" />
  </joint>

  <link name="RL_foot">
    <inertial>
      <origin xyz="0 0 0" rpy="0 0 0" />
      <mass value="0.04" />
      <inertia ixx="9.6e-06" ixy="0" ixz="0" iyy="9.6e-06" iyz="0" izz="9.6e-06" />
    </inertial>
    <visual>
      <origin xyz="0 0 0" rpy="0 0 0" />
      <geometry>
        <sphere radius="0.026" />
      </geometry>
      <material name="">
        <color rgba="1 1 0.4 1" />
      </material>
    </visual>
    <collision>
      <origin xyz="0 0 0" rpy="0 0 0" />
      <geometry>
        <sphere radius="0.026" />
      </geometry>
    </collision>
    <!-- template_collision_placeholder -->
  </link>

  <joint name="RL_foot_joint" type="fixed" dont_collapse="true">
    <origin xyz="0 0 -0.26" rpy="0 0 0" />
    <parent link="RL_calf" />
    <child link="RL_foot" />
    <axis xyz="0 1 0" />
    <limit lower="0" upper="0" effort="0" velocity="0" />
  </joint>

  <link name="FR_hip">
    <inertial>
      <origin xyz="-0.0034539 -0.0001471 -0.0009605" rpy="0 0 0" />
      <mass value="1.6459372" />
      <inertia ixx="0.0004144" iyy="0.000796" izz="0.0005767" ixy="-1e-05" ixz="1.5e-06" iyz="1.4e-06" />
    </inertial>
    <visual>
      <origin xyz="0 0 0" rpy="0 0 0" />
      <geometry>
        <mesh filename="package://galileo_v1d6_description/meshes/FL_HIP.STL" scale="1.0 -1.0 1.0" />
      </geometry>
      <material name="">
        <color rgba="1 0.4 0.4 1" />
      </material>
    </visual>
    <!-- <collision>
      <origin xyz="0 0 0" rpy="0 0 0"/>
      <geometry>
        <mesh filename="package://galileo_v1d6_description/meshes/FL_HIP.STL" scale="1.0 -1.0 1.0"/>
      </geometry>
    </collision> -->
    <!-- template_collision_placeholder -->
  </link>

  <joint name="FR_hip_joint" type="revolute">
    <origin xyz="0.279 -0.067 0.0" rpy="-0.0 0.0 -0.0" />
    <parent link="base_link" />
    <child link="FR_hip" />
    <axis xyz="1 0 0" />
    <limit lower="-0.698132" upper="0.698132" effort="120" velocity="12.0" />
  </joint>

  <link name="FR_thigh">
    <inertial>
      <origin xyz="-0.0028001 0.0368096 -0.0239021" rpy="0 0 0" />
      <mass value="2.2115554" />
      <inertia ixx="0.012133" iyy="0.0117725" izz="0.0019164" ixy="-0.0002099" ixz="-0.000542" iyz="-0.0020399" />
    </inertial>
    <visual>
      <origin xyz="0 0 0" rpy="0 0 0" />
      <geometry>
        <mesh filename="package://galileo_v1d6_description/meshes/FL_THIGH.STL" scale="1.0 -1.0 1.0" />
      </geometry>
      <material name="">
        <color rgba="1 1 0.4 1" />
      </material>
    </visual>
    <collision>
      <origin xyz="-0.025 0 -0.15" rpy="0 0 0" />
      <geometry>
        <box size="0.05 0.02 0.18" />
      </geometry>
    </collision>
    <collision>
      <origin xyz="0 0.065 0" rpy="1.57 1.57 0" />
      <geometry>
        <cylinder radius="0.06" length="0.08" />
      </geometry>
    </collision>
    <!-- template_collision_placeholder -->
  </link>

  <joint name="FR_thigh_joint" type="revolute">
    <origin xyz="0.0 -0.1103 0.0" rpy="-0.0 0.0 -0.0" />
    <parent link="FR_hip" />
    <child link="FR_thigh" />
    <axis xyz="0 1 0" />
    <limit lower="-1.762783" upper="3.647738" effort="120" velocity="12.0" />
  </joint>

  <link name="FR_calf">
    <inertial>
      <origin xyz="0.006276 -6e-05 -0.1458107" rpy="0 0 0" />
      <mass value="0.3248308" />
      <inertia ixx="0.0041942" iyy="0.0042423" izz="9.93e-05" ixy="-0.0" ixz="-3e-07" iyz="-0.0" />
    </inertial>
    <visual>
      <origin xyz="0 0 0" rpy="0 0 0" />
      <geometry>
        <mesh filename="package://galileo_v1d6_description/meshes/FL_CALF.STL" scale="1.0 -1.0 1.0" />
      </geometry>
      <material name="">
        <color rgba="0.4 1 0.4 1" />
      </material>
    </visual>
    <collision>
      <origin xyz="0.015 0.0 -0.235" rpy="0 0.5 0" />
      <geometry>
        <box size="0.04 0.02 0.05" />
      </geometry>
    </collision>
    <collision>
      <origin xyz="0.0085 0.0 -0.092" rpy="0 -0.15 0" />
      <geometry>
        <box size="0.032 0.02 0.27" />
      </geometry>
    </collision>
    <!-- template_collision_placeholder -->
  </link>

  <joint name="FR_calf_joint" type="revolute">
    <origin xyz="0.0 -0.0 -0.26" rpy="-0.0 0.0 -0.0" />
    <parent link="FR_thigh" />
    <child link="FR_calf" />
    <axis xyz="0 1 0" />
    <limit lower="-2.740167" upper="-0.383972" effort="120" velocity="12.0" />
  </joint>

  <link name="FR_foot">
    <inertial>
      <origin xyz="0 0 0" rpy="0 0 0" />
      <mass value="0.04" />
      <inertia ixx="9.6e-06" ixy="0" ixz="0" iyy="9.6e-06" iyz="0" izz="9.6e-06" />
    </inertial>
    <visual>
      <origin xyz="0 0 0" rpy="0 0 0" />
      <geometry>
        <sphere radius="0.026" />
      </geometry>
      <material name="">
        <color rgba="0 0.5 1 1" />
      </material>
    </visual>
    <collision>
      <origin xyz="0 0 0" rpy="0 0 0" />
      <geometry>
        <sphere radius="0.026" />
      </geometry>
    </collision>
    <!-- template_collision_placeholder -->
  </link>

  <joint name="FR_foot_joint" type="fixed" dont_collapse="true">
    <origin xyz="0.0 -0.0 -0.26" rpy="-0.0 0.0 -0.0" />
    <parent link="FR_calf" />
    <child link="FR_foot" />
    <axis xyz="0 1 0" />
    <limit lower="0" upper="0" effort="0" velocity="0" />
  </joint>

  <link name="RR_hip">
    <inertial>
      <origin xyz="-0.0034539 -0.0001471 -0.0009605" rpy="0 0 0" />
      <mass value="1.6459372" />
      <inertia ixx="0.0004144" iyy="0.000796" izz="0.0005767" ixy="1e-05" ixz="-1.5e-06" iyz="1.4e-06" />
    </inertial>
    <visual>
      <origin xyz="0 0 0" rpy="0 0 0" />
      <geometry>
        <mesh filename="package://galileo_v1d6_description/meshes/RL_HIP.STL" scale="1.0 -1.0 1.0" />
      </geometry>
      <material name="">
        <color rgba="0.8 1.0 0.8 1" />
      </material>
    </visual>
    <!-- <collision>
      <origin xyz="0 0 0" rpy="0 0 0"/>
      <geometry>
        <mesh filename="package://galileo_v1d6_description/meshes/RL_HIP.STL" scale="1.0 -1.0 1.0"/>
      </geometry>
    </collision> -->
    <!-- template_collision_placeholder -->
  </link>

  <joint name="RR_hip_joint" type="revolute">
    <origin xyz="-0.279 -0.067 0.0" rpy="-0.0 0.0 -0.0" />
    <parent link="base_link" />
    <child link="RR_hip" />
    <axis xyz="1 0 0" />
    <limit lower="-0.698132" upper="0.698132" effort="120" velocity="12.0" />
  </joint>

  <link name="RR_thigh">
    <inertial>
      <origin xyz="-0.0028001 0.0368096 -0.0239021" rpy="0 0 0" />
      <mass value="2.2115554" />
      <inertia ixx="0.012133" iyy="0.0117725" izz="0.0019164" ixy="-0.0002099" ixz="-0.000542" iyz="-0.0020399" />
    </inertial>
    <visual>
      <origin xyz="0 0 0" rpy="0 0 0" />
      <geometry>
        <mesh filename="package://galileo_v1d6_description/meshes/FL_THIGH.STL" scale="1.0 -1.0 1.0" />
      </geometry>
      <material name="">
        <color rgba="1 0.5 1 1" />
      </material>
    </visual>
    <collision>
      <origin xyz="-0.025 0 -0.15" rpy="0 0 0" />
      <geometry>
        <box size="0.05 0.02 0.18" />
      </geometry>
    </collision>
    <collision>
      <origin xyz="0 0.065 0" rpy="1.57 1.57 0" />
      <geometry>
        <cylinder radius="0.06" length="0.08" />
      </geometry>
    </collision>
    <!-- template_collision_placeholder -->
  </link>

  <joint name="RR_thigh_joint" type="revolute">
    <origin xyz="0.0 -0.1103 0.0" rpy="-0.0 0.0 -0.0" />
    <parent link="RR_hip" />
    <child link="RR_thigh" />
    <axis xyz="0 1 0" />
    <limit lower="-1.762783" upper="3.647738" effort="120" velocity="12.0" />
  </joint>

  <link name="RR_calf">
    <inertial>
      <origin xyz="0.006276 -6e-05 -0.1458107" rpy="0 0 0" />
      <mass value="0.3248308" />
      <inertia ixx="0.0041942" iyy="0.0042423" izz="9.93e-05" ixy="-0.0" ixz="-3e-07" iyz="-0.0" />
    </inertial>
    <visual>
      <origin xyz="0 0 0" rpy="0 0 0" />
      <geometry>
        <mesh filename="package://galileo_v1d6_description/meshes/FL_CALF.STL" scale="1.0 -1.0 1.0" />
      </geometry>
      <material name="">
        <color rgba="1 0.4 0.4 1" />
      </material>
    </visual>
    <collision>
      <origin xyz="0.015 0.0 -0.235" rpy="0 0.5 0" />
      <geometry>
        <box size="0.04 0.02 0.05" />
      </geometry>
    </collision>
    <collision>
      <origin xyz="0.0085 0.0 -0.092" rpy="0 -0.15 0" />
      <geometry>
        <box size="0.032 0.02 0.27" />
      </geometry>
    </collision>
    <!-- template_collision_placeholder -->
  </link>

  <joint name="RR_calf_joint" type="revolute">
    <origin xyz="0.0 -0.0 -0.26" rpy="-0.0 0.0 -0.0" />
    <parent link="RR_thigh" />
    <child link="RR_calf" />
    <axis xyz="0 1 0" />
    <limit lower="-2.740167" upper="-0.383972" effort="120" velocity="12.0" />
  </joint>

  <link name="RR_foot">
    <inertial>
      <origin xyz="0 0 0" rpy="0 0 0" />
      <mass value="0.04" />
      <inertia ixx="9.6e-06" ixy="0" ixz="0" iyy="9.6e-06" iyz="0" izz="9.6e-06" />
    </inertial>
    <visual>
      <origin xyz="0 0 0" rpy="0 0 0" />
      <geometry>
        <sphere radius="0.026" />
      </geometry>
      <material name="">
        <color rgba="1 1 0.4 1" />
      </material>
    </visual>
    <collision>
      <origin xyz="0 0 0" rpy="0 0 0" />
      <geometry>
        <sphere radius="0.026" />
      </geometry>
    </collision>
    <!-- template_collision_placeholder -->
  </link>

  <joint name="RR_foot_joint" type="fixed" dont_collapse="true">
    <origin xyz="0.0 -0.0 -0.26" rpy="-0.0 0.0 -0.0" />
    <parent link="RR_calf" />
    <child link="RR_foot" />
    <axis xyz="0 1 0" />
    <limit lower="0" upper="0" effort="0" velocity="0" />
  </joint>

  <link name="link0">
    <inertial>
      <origin xyz="-3.0001E-05 3.0589E-05 0.027324" rpy="0 0 0" />
      <mass value="0.43995" />
      <inertia ixx="0.00017" ixy="0.00000" ixz="0.00000" iyy="0.00017" iyz="0.00000" izz="0.00016" />
    </inertial>
    <visual>
      <origin xyz="0 0 0" rpy="0 0 0" />
      <geometry>
        <mesh filename="package://galileo_v1d6_x5_description/meshes/link0.STL" />
      </geometry>
      <material name="">
        <color rgba="0.75294 0.75294 0.75294 1" />
      </material>
    </visual>
    <collision>
      <origin xyz="0 0 0.03" rpy="0 0 0" />
      <geometry>
        <cylinder radius="0.03" length="0.06" />
      </geometry>
    </collision>
  </link>

  <joint name="link0_joint" type="fixed" dont_collapse="true">
    <origin xyz="0.18 0.0 0.08" rpy="0.0 0.0 0.0" />
    <parent link="base_link" />
    <child link="link0" />
  </joint>

  <link name="link1">
    <inertial>
      <origin xyz="0.0054231 -0.0080289 0.017086" rpy="0 0 0" />
      <mass value="0.066982" />
      <inertia ixx="0.00008" ixy="0.00000" ixz="0.00001" iyy="0.00003" iyz="0.00000" izz="0.00008" />
    </inertial>
    <visual>
      <origin xyz="0 0 0" rpy="0 0 0" />
      <geometry>
        <mesh filename="package://galileo_v1d6_x5_description/meshes/link1.STL" />
      </geometry>
      <material name="">
        <color rgba="0.79216 0.81961 0.93333 1" />
      </material>
    </visual>
  </link>

  <joint name="joint1" type="revolute">
    <origin xyz="0 0 0.0605" rpy="0 0 0" />
    <parent link="link0" />
    <child link="link1" />
    <axis xyz="0 0 1" />
    <limit lower="-3.14" upper="2.6" effort="100" velocity="1000" />
  </joint>

  <link name="link2">
    <inertial>
      <origin xyz="-0.13237 0.0020852 0.00010549" rpy="0 0 0" />
      <mass value="1.0795" />
      <inertia ixx="0.00051" ixy="0.00001" ixz="-0.00004" iyy="0.01599" iyz="0.00000" izz="0.01605" />
    </inertial>
    <visual>
      <origin xyz="0 0 0" rpy="0 0 0" />
      <geometry>
        <mesh filename="package://galileo_v1d6_x5_description/meshes/link2.STL" />
      </geometry>
      <material name="">
        <color rgba="0.75294 0.75294 0.75294 1" />
      </material>
    </visual>
    <collision>
      <origin xyz="0 0 0" rpy="1.57 0 0" />
      <geometry>
        <cylinder radius="0.03" length="0.06" />
      </geometry>
    </collision>
    <collision>
      <origin xyz="-0.13 0 0" rpy="0 0 0" />
      <geometry>
        <box size="0.22 0.06 0.05" />
      </geometry>
    </collision>
    <collision>
      <origin xyz="-0.26 0 0" rpy="1.57 0 0" />
      <geometry>
        <cylinder radius="0.03" length="0.06" />
      </geometry>
    </collision>
  </link>

  <joint name="joint2" type="revolute">
    <origin xyz="0.02 0 0.04" rpy="0 0 0" />
    <parent link="link1" />
    <child link="link2" />
    <axis xyz="0 1 0" />
    <limit lower="-0.1" upper="3.6" effort="100" velocity="1000" />
  </joint>

  <link name="link3">
    <inertial>
      <origin xyz="0.18531 0.00068376 -0.051638" rpy="0 0 0" />
      <mass value="0.54534" />
      <inertia ixx="0.00036" ixy="-0.00003" ixz="-0.00039" iyy="0.00423" iyz="0.00001" izz="0.00420" />
    </inertial>
    <visual>
      <origin xyz="0 0 0" rpy="0 0 0" />
      <geometry>
        <mesh filename="package://galileo_v1d6_x5_description/meshes/link3.STL" />
      </geometry>
      <material name="">
        <color rgba="1 0.98431 0.96471 1" />
      </material>
    </visual>
    <collision>
      <origin xyz="0.245 0 -0.056" rpy="1.57 0 0" />
      <geometry>
        <cylinder radius="0.028" length="0.05" />
      </geometry>
    </collision>
    <collision>
      <origin xyz="0.135 0 -0.056" rpy="0 0 0" />
      <geometry>
        <box size="0.19 0.05 0.04" />
      </geometry>
    </collision>
  </link>

  <joint name="joint3" type="revolute">
    <origin xyz="-0.264 0 0" rpy="3.1416 0 0" />
    <parent link="link2" />
    <child link="link3" />
    <axis xyz="0 1 0" />
    <limit lower="0" upper="3.14" effort="100" velocity="1000" />
  </joint>

  <link name="link4">
    <inertial>
      <origin xyz="0.040231 0.0044807 -0.035335" rpy="0 0 0" />
      <mass value="0.11714" />
      <inertia ixx="0.00019" ixy="-0.00002" ixz="-0.00009" iyy="0.00023" iyz="0.00002" izz="0.00014" />
    </inertial>
    <visual>
      <origin xyz="0 0 0" rpy="0 0 0" />
      <geometry>
        <mesh filename="package://galileo_v1d6_x5_description/meshes/link4.STL" />
      </geometry>
      <material name="">
        <color rgba="0.79216 0.81961 0.92941 1" />
      </material>
    </visual>
    <collision>
      <origin xyz="0.068 0 -0.066" rpy="0 0 0" />
      <geometry>
        <cylinder radius="0.03" length="0.04" />
      </geometry>
    </collision>
  </link>

  <joint name="joint4" type="revolute">
    <origin xyz="0.245 0 -0.056" rpy="0 0 0" />
    <parent link="link3" />
    <child link="link4" />
    <axis xyz="0 1 0" />
    <limit lower="-1.3" upper="1.3" effort="100" velocity="1000" />
  </joint>

  <link name="link5">
    <inertial>
      <origin xyz="0.003612 -1.5455E-05 0.055214" rpy="0 0 0" />
      <mass value="0.63488" />
      <inertia ixx="0.00083" ixy="0.00000" ixz="0.00007" iyy="0.00082" iyz="0.00000" izz="0.00026" />
    </inertial>
    <visual>
      <origin xyz="0 0 0" rpy="0 0 0" />
      <geometry>
        <mesh filename="package://galileo_v1d6_x5_description/meshes/link5.STL" />
      </geometry>
      <material name="">
        <color rgba="0.69804 0.69804 0.69804 1" />
      </material>
    </visual>
    <collision>
      <origin xyz="0.005 0 0.086" rpy="0 1.57 0" />
      <geometry>
        <cylinder radius="0.03" length="0.04" />
      </geometry>
    </collision>
  </link>

  <joint name="joint5" type="revolute">
    <origin xyz="0.06775 0.0005 -0.0865" rpy="0 0 0" />
    <parent link="link4" />
    <child link="link5" />
    <axis xyz="0 0 1" />
    <limit lower="-1.57" upper="1.57" effort="100" velocity="1000" />
  </joint>

  <link name="link6">
    <inertial>
      <origin xyz="0.041697 2.4368E-05 0.00014464" rpy="0 0 0" />
      <mass value="0.44089" />
      <inertia ixx="0.00038" ixy="0.00000" ixz="0.00000" iyy="0.00028" iyz="0.00000" izz="0.00050" />
    </inertial>
    <visual>
      <origin xyz="0 0 0" rpy="0 0 0" />
      <geometry>
        <mesh filename="package://galileo_v1d6_x5_description/meshes/link6.STL" />
      </geometry>
      <material name="">
        <color rgba="0.89804 0.91765 0.92941 1" />
      </material>
    </visual>
    <collision>
      <origin xyz="0.03 0 0" rpy="0 1.57 0" />
      <geometry>
        <cylinder radius="0.03" length="0.06" />
      </geometry>
    </collision>
  </link>

  <joint name="joint6" type="revolute">
    <origin xyz="0.02895 0 0.0865" rpy="-3.1416 0 0" />
    <parent link="link5" />
    <child link="link6" />
    <axis xyz="1 0 0" />
    <limit lower="-2.1" upper="2.1" effort="100" velocity="1000" />
  </joint>

  <link name="link7">
    <inertial>
      <origin xyz="-0.00035522 -0.007827 -0.0029883" rpy="0 0 0" />
      <mass value="0.064798" />
      <inertia ixx="0.00002" ixy="0.00000" ixz="0.00000" iyy="0.00003" iyz="0.00000" izz="0.00003" />
    </inertial>
    <visual>
      <origin xyz="0 0 0" rpy="0 0 0" />
      <geometry>
        <mesh filename="package://galileo_v1d6_x5_description/meshes/link7.STL" />
      </geometry>
      <material name="">
        <color rgba="1 1 1 1" />
      </material>
    </visual>
    <collision>
      <origin xyz="0 0 0" rpy="0 0 0" />
      <geometry>
        <mesh filename="package://galileo_v1d6_x5_description/meshes/link7.STL" />
      </geometry>
    </collision>
  </link>

  <joint name="joint7" type="prismatic">
    <origin xyz="0.08657 0.024896 -0.0002436" rpy="0 0 0" />
    <parent link="link6" />
    <child link="link7" />
    <axis xyz="0 1 0" />
    <limit lower="0" upper="0.044" effort="100" velocity="1000" />
  </joint>

  <link name="link8">
    <inertial>
      <origin xyz="-0.00035522 0.0078277 0.0024201" rpy="0 0 0" />
      <mass value="0.064798" />
      <inertia ixx="0.00002" ixy="0.00000" ixz="0.00000" iyy="0.00003" iyz="0.00000" izz="0.00003" />
    </inertial>
    <visual>
      <origin xyz="0 0 0" rpy="0 0 0" />
      <geometry>
        <mesh filename="package://galileo_v1d6_x5_description/meshes/link8.STL" />
      </geometry>
      <material name="">
        <color rgba="1 1 1 1" />
      </material>
    </visual>
    <collision>
      <origin xyz="0 0 0" rpy="0 0 0" />
      <geometry>
        <mesh filename="package://galileo_v1d6_x5_description/meshes/link8.STL" />
      </geometry>
    </collision>
  </link>

  <joint name="joint8" type="prismatic">
    <origin xyz="0.08657 -0.0249 -0.00024366" rpy="0 0 0" />
    <parent link="link6" />
    <child link="link8" />
    <axis xyz="0 -1 0" />
    <limit lower="0" upper="0.044" effort="100" velocity="1000" />
  </joint>

</robot>