<mujoco model="galileo_mini_x5_description">
    <compiler angle="radian" meshdir="../meshes/" autolimits="true" />
    
  <asset>
    <mesh name="base_link" file="base_link.STL" />
    <mesh name="FL_abd_link" file="FL_abd_link.STL" />
    <mesh name="FL_hip_link" file="FL_hip_link.STL" />
    <mesh name="FL_knee_link" file="FL_knee_link.STL" />
    <mesh name="FR_abd_link" file="FR_abd_link.STL" />
    <mesh name="FR_hip_link" file="FR_hip_link.STL" />
    <mesh name="FR_knee_link" file="FR_knee_link.STL" />
    <mesh name="HL_abd_link" file="HL_abd_link.STL" />
    <mesh name="HL_hip_link" file="HL_hip_link.STL" />
    <mesh name="HL_knee_link" file="HL_knee_link.STL" />
    <mesh name="HR_abd_link" file="HR_abd_link.STL" />
    <mesh name="HR_hip_link" file="HR_hip_link.STL" />
    <mesh name="HR_knee_link" file="HR_knee_link.STL" />
    <mesh name="manipulator_base_link" file="manipulator_base_link.STL" />
    <mesh name="link1" file="link1.STL" />
    <mesh name="link2" file="link2.STL" />
    <mesh name="link3" file="link3.STL" />
    <mesh name="link4" file="link4.STL" />
    <mesh name="link5" file="link5.STL" />
    <mesh name="link6" file="link6.STL" />
    <mesh name="link7" file="link7.STL" />
    <mesh name="link8" file="link8.STL" />
    <texture type="skybox" builtin="gradient" rgb1="0.3 0.5 0.7" rgb2="0 0 0" width="512"
      height="3072" />
    <texture type="2d" name="groundplane" builtin="checker" mark="edge" rgb1="0.2 0.3 0.4"
      rgb2="0.1 0.2 0.3"
      markrgb="0.8 0.8 0.8" width="300" height="300" />
    <material name="groundplane" texture="groundplane" texuniform="true" texrepeat="5 5"
      reflectance="0.2" />
  </asset>

  <visual>
    <headlight diffuse="0.6 0.6 0.6" ambient="0.3 0.3 0.3" specular="0 0 0" />
    <rgba haze="0.15 0.25 0.35 1" />
    <global azimuth="-130" elevation="-20" />
  </visual>

  <worldbody>
    <light pos="0 0 1.5" dir="0 0 -1" directional="true" />
    <geom name="floor" size="0 0 0.05" type="plane" material="groundplane" />
    <body name="base_link" pos="0 0 0.7">
      <inertial pos="0.0386764 -0.00645316 0.00789644" quat="0.0148433 0.705531 0.010334 0.708448"
        mass="21.24" diaginertia="0.47871 0.414143 0.135715" />
      <joint name="floating_base_joint" type="free" limited="false" actuatorfrclimited="false" />
      <geom type="mesh" contype="0" conaffinity="0" group="1" density="0"
        rgba="0.75294 0.75294 0.75294 1" mesh="base_link" />
      <geom size="0.225 0.125 0.05" type="box" rgba="0.75294 0.75294 0.75294 1" />
      <geom pos="0.1 0 0.08" quat="1 0 0 0" type="mesh" contype="0" conaffinity="0" group="1"
        density="0" rgba="0.75294 0.75294 0.75294 1" mesh="manipulator_base_link" />
      <geom pos="0.1 0 0.08" quat="1 0 0 0" type="mesh" rgba="0.75294 0.75294 0.75294 1"
        mesh="manipulator_base_link" />
      <site name="site_imu" pos="0 0 0" />

      <body name="FL_abd_link" pos="0.2015 0.08 0">
        <inertial pos="0.067568 0.0095934 1.3738e-05" quat="0.500634 0.554466 0.463464 0.476585"
          mass="2.86" diaginertia="0.00752069 0.00677878 0.00432153" />
        <joint name="FL_abd_joint" pos="0 0 0" axis="1 0 0" range="-0.80285 0.80285"
          actuatorfrcrange="-100 100" />
        <geom type="mesh" contype="0" conaffinity="0" group="1" density="0"
          rgba="0.75294 0.75294 0.75294 1" mesh="FL_abd_link" />
        <geom size="0.06 0.05325" pos="0.1 0.03325 0" quat="0.707107 0.707107 0 0" type="cylinder"
          rgba="0.75294 0.75294 0.75294 1" />
        <body name="FL_hip_link" pos="0.1 0.1065 0">
          <inertial pos="-0.0090988 -0.0065295 -0.0688"
            quat="0.419807 -0.0627305 0.0522402 0.903935" mass="2.6"
            diaginertia="0.017487 0.0165271 0.00167088" />
          <joint name="FL_hip_joint" pos="0 0 0" axis="0 1 0" range="-1.0472 4.1888"
            actuatorfrcrange="-100 100" />
          <geom type="mesh" contype="0" conaffinity="0" group="1" density="0"
            rgba="0.75294 0.75294 0.75294 1" mesh="FL_hip_link" />
          <geom size="0.03 0.0175 0.13" pos="-0.025 0 -0.08" type="box"
            rgba="0.75294 0.75294 0.75294 1" />
          <body name="FL_knee_link" pos="0 0 -0.26">
            <inertial pos="0.0178389 -1.57597e-05 -0.0993188"
              quat="0.703247 0.0575451 0.0571447 0.706305" mass="0.314205"
              diaginertia="0.00388744 0.0038366 7.88395e-05" />
            <joint name="FL_knee_joint" pos="0 0 0" axis="0 1 0" range="-2.6965 -0.9163"
              actuatorfrcrange="-150 150" />
            <geom type="mesh" contype="0" conaffinity="0" group="1" density="0"
              rgba="0.75294 0.75294 0.75294 1" mesh="FL_knee_link" />
            <geom size="0.025 0.015 0.115" pos="0.0164695 0 -0.13" quat="0.996195 0 -0.0871543 0"
              type="box" rgba="0.75294 0.75294 0.75294 1" />
            <geom size="0.03" pos="0.032939 0 -0.26149" contype="0" conaffinity="0" group="1"
              density="0" rgba="1 1 1 1" />
            <geom size="0.03" pos="0.032939 0 -0.26149" rgba="1 1 1 1" />
          </body>
        </body>
      </body>
      <body name="FR_abd_link" pos="0.2015 -0.08 0">
        <inertial pos="0.067568 -0.0091759 -0.00023747" quat="0.461518 0.473275 0.50733 0.552837"
          mass="2.86" diaginertia="0.00753518 0.00677611 0.00431971" />
        <joint name="FR_abd_joint" pos="0 0 0" axis="1 0 0" range="-0.80285 0.80285"
          actuatorfrcrange="-100 100" />
        <geom type="mesh" contype="0" conaffinity="0" group="1" density="0"
          rgba="0.75294 0.75294 0.75294 1" mesh="FR_abd_link" />
        <geom size="0.06 0.05325" pos="0.1 -0.03325 0" quat="0.707107 0.707107 0 0" type="cylinder"
          rgba="0.75294 0.75294 0.75294 1" />
        <body name="FR_hip_link" pos="0.1 -0.10685 0">
          <inertial pos="-0.0095338 0.026092 -0.067392"
            quat="0.870643 0.0549937 -0.0729496 0.483357" mass="2.6"
            diaginertia="0.017109 0.016051 0.00168403" />
          <joint name="FR_hip_joint" pos="0 0 0" axis="0 1 0" range="-1.0472 4.1888"
            actuatorfrcrange="-100 100" />
          <geom type="mesh" contype="0" conaffinity="0" group="1" density="0"
            rgba="0.75294 0.75294 0.75294 1" mesh="FR_hip_link" />
          <geom size="0.03 0.0175 0.13" pos="-0.025 0 -0.08" type="box"
            rgba="0.75294 0.75294 0.75294 1" />
          <body name="FR_knee_link" pos="0 0 -0.26">
            <inertial pos="0.0178389 -1.57597e-05 -0.0993188"
              quat="0.703247 0.0575451 0.0571447 0.706305" mass="0.314205"
              diaginertia="0.00388744 0.0038366 7.88395e-05" />
            <joint name="FR_knee_joint" pos="0 0 0" axis="0 1 0" range="-2.6965 -0.9163"
              actuatorfrcrange="-150 150" />
            <geom type="mesh" contype="0" conaffinity="0" group="1" density="0"
              rgba="0.75294 0.75294 0.75294 1" mesh="FR_knee_link" />
            <geom size="0.025 0.015 0.115" pos="0.0164695 0 -0.13" quat="0.996195 0 -0.0871543 0"
              type="box" rgba="0.75294 0.75294 0.75294 1" />
            <geom size="0.03" pos="0.032939 0 -0.26149" contype="0" conaffinity="0" group="1"
              density="0" rgba="1 1 1 1" />
            <geom size="0.03" pos="0.032939 0 -0.26149" rgba="1 1 1 1" />
          </body>
        </body>
      </body>
      <body name="HL_abd_link" pos="-0.2015 0.08 0">
        <inertial pos="-0.06741 0.0095934 7.3103e-05" quat="0.554404 0.501113 0.477741 0.461829"
          mass="2.86" diaginertia="0.00751653 0.00676882 0.00432565" />
        <joint name="HL_abd_joint" pos="0 0 0" axis="1 0 0" range="-0.80285 0.80285"
          actuatorfrcrange="-100 100" />
        <geom type="mesh" contype="0" conaffinity="0" group="1" density="0"
          rgba="0.75294 0.75294 0.75294 1" mesh="HL_abd_link" />
        <geom size="0.06 0.05325" pos="-0.1 0.03325 0" quat="0.707107 0.707107 0 0" type="cylinder"
          rgba="0.75294 0.75294 0.75294 1" />
        <body name="HL_hip_link" pos="-0.1 0.1065 0">
          <inertial pos="-0.0090357 -0.0065295 -0.0688"
            quat="0.419807 -0.0627305 0.0522402 0.903935" mass="2.6"
            diaginertia="0.017487 0.0165271 0.00167088" />
          <joint name="HL_hip_joint" pos="0 0 0" axis="0 1 0" range="-1.0472 4.1888"
            actuatorfrcrange="-100 100" />
          <geom type="mesh" contype="0" conaffinity="0" group="1" density="0"
            rgba="0.75294 0.75294 0.75294 1" mesh="HL_hip_link" />
          <geom size="0.03 0.0175 0.13" pos="-0.025 0 -0.08" type="box"
            rgba="0.75294 0.75294 0.75294 1" />
          <body name="HL_knee_link" pos="6.3209e-05 0 -0.26">
            <inertial pos="0.0178389 -1.57597e-05 -0.0993188"
              quat="0.703247 0.0575451 0.0571447 0.706305" mass="0.314205"
              diaginertia="0.00388744 0.0038366 7.88395e-05" />
            <joint name="HL_knee_joint" pos="0 0 0" axis="0 1 0" range="-2.6965 -0.9163"
              actuatorfrcrange="-150 150" />
            <geom type="mesh" contype="0" conaffinity="0" group="1" density="0"
              rgba="0.75294 0.75294 0.75294 1" mesh="HL_knee_link" />
            <geom size="0.025 0.015 0.115" pos="0.0164695 0 -0.13" quat="0.996195 0 -0.0871543 0"
              type="box" rgba="0.75294 0.75294 0.75294 1" />
            <geom size="0.03" pos="0.0329385 0 -0.261493" contype="0" conaffinity="0" group="1"
              density="0" rgba="1 1 1 1" />
            <geom size="0.03" pos="0.0329385 0 -0.261493" rgba="1 1 1 1" />
          </body>
        </body>
      </body>
      <body name="HR_abd_link" pos="-0.2015 -0.08 0">
        <inertial pos="-0.067556 -0.0095934 -1.7463e-05" quat="0.554404 0.501113 0.477741 0.461829"
          mass="2.86" diaginertia="0.00751653 0.00676882 0.00432565" />
        <joint name="HR_abd_joint" pos="0 0 0" axis="1 0 0" range="-0.80285 0.80285"
          actuatorfrcrange="-100 100" />
        <geom type="mesh" contype="0" conaffinity="0" group="1" density="0"
          rgba="0.75294 0.75294 0.75294 1" mesh="HR_abd_link" />
        <geom size="0.06 0.05325" pos="-0.1 -0.03325 0" quat="0.707107 0.707107 0 0" type="cylinder"
          rgba="0.75294 0.75294 0.75294 1" />
        <body name="HR_hip_link" pos="-0.1 -0.10685 0">
          <inertial pos="-0.0098055 0.020667 -0.067167"
            quat="0.935391 0.0800659 -0.0651055 0.338223" mass="2.6"
            diaginertia="0.0175517 0.0167351 0.0022722" />
          <joint name="HR_hip_joint" pos="0 0 0" axis="0 1 0" range="-1.0472 4.1888"
            actuatorfrcrange="-100 100" />
          <geom type="mesh" contype="0" conaffinity="0" group="1" density="0"
            rgba="0.75294 0.75294 0.75294 1" mesh="HR_hip_link" />
          <geom size="0.03 0.0175 0.13" pos="-0.025 0 -0.08" type="box"
            rgba="0.75294 0.75294 0.75294 1" />
          <body name="HR_knee_link" pos="0 0 -0.26">
            <inertial pos="0.0178389 -1.57597e-05 -0.0993188"
              quat="0.703247 0.0575451 0.0571447 0.706305" mass="0.314205"
              diaginertia="0.00388744 0.0038366 7.88395e-05" />
            <joint name="HR_knee_joint" pos="0 0 0" axis="0 1 0" range="-2.6965 -0.9163"
              actuatorfrcrange="-150 150" />
            <geom type="mesh" contype="0" conaffinity="0" group="1" density="0"
              rgba="0.75294 0.75294 0.75294 1" mesh="HR_knee_link" />
            <geom size="0.025 0.015 0.115" pos="0.0164695 0 -0.13" quat="0.996195 0 -0.0871543 0"
              type="box" rgba="0.75294 0.75294 0.75294 1" />
            <geom size="0.03" pos="0.032939 0 -0.26149" contype="0" conaffinity="0" group="1"
              density="0" rgba="1 1 1 1" />
            <geom size="0.03" pos="0.032939 0 -0.26149" rgba="1 1 1 1" />
          </body>
        </body>
      </body>
      <body name="link1" pos="0.1 0 0.1405">
        <inertial pos="0.0054231 -0.0080289 0.017086" quat="0.653281 0.653281 -0.270598 0.270598"
          mass="0.066982" diaginertia="9e-05 7e-05 3e-05" />
        <joint name="joint1" pos="0 0 0" axis="0 0 1" range="-10 10" actuatorfrcrange="-100 100" />
        <geom type="mesh" contype="0" conaffinity="0" group="1" density="0"
          rgba="0.79216 0.81961 0.93333 1" mesh="link1" />
        <geom type="mesh" rgba="0.79216 0.81961 0.93333 1" mesh="link1" />
        <body name="link2" pos="0.02 0 0.04">
          <inertial pos="-0.13237 0.0020852 0.00010549"
            quat="7.64729e-05 0.706196 -0.000379919 0.708016" mass="1.0795"
            diaginertia="0.0160501 0.01599 0.000509891" />
          <joint name="joint2" pos="0 0 0" axis="0 1 0" range="-10 10" actuatorfrcrange="-100 100" />
          <geom type="mesh" contype="0" conaffinity="0" group="1" density="0"
            rgba="0.75294 0.75294 0.75294 1" mesh="link2" />
          <geom type="mesh" rgba="0.75294 0.75294 0.75294 1" mesh="link2" />
          <body name="link3" pos="-0.264 0 0" quat="-3.67321e-06 1 0 0">
            <inertial pos="0.18531 0.00068376 -0.051638" quat="0.223261 0.638184 0.206685 0.707218"
              mass="0.54534" diaginertia="0.00424842 0.004221 0.000320578" />
            <joint name="joint3" pos="0 0 0" axis="0 1 0" range="-10 10" actuatorfrcrange="-100 100" />
            <geom type="mesh" contype="0" conaffinity="0" group="1" density="0"
              rgba="1 0.98431 0.96471 1" mesh="link3" />
            <geom type="mesh" rgba="1 0.98431 0.96471 1" mesh="link3" />
            <body name="link4" pos="0.245 0 -0.056">
              <inertial pos="0.040231 0.0044807 -0.035335"
                quat="0.911288 -0.0751532 0.308689 -0.261949" mass="0.11714"
                diaginertia="0.000275643 0.00021286 7.14977e-05" />
              <joint name="joint4" pos="0 0 0" axis="0 1 0" range="-10 10"
                actuatorfrcrange="-100 100" />
              <geom type="mesh" contype="0" conaffinity="0" group="1" density="0"
                rgba="0.79216 0.81961 0.92941 1" mesh="link4" />
              <geom type="mesh" rgba="0.79216 0.81961 0.92941 1" mesh="link4" />
              <body name="link5" pos="0.06775 0.0005 -0.0865">
                <inertial pos="0.003612 -1.5455e-05 0.055214" quat="0.998188 0 -0.0601752 0"
                  mass="0.63488" diaginertia="0.000838471 0.00082 0.000251529" />
                <joint name="joint5" pos="0 0 0" axis="0 0 1" range="-10 10"
                  actuatorfrcrange="-100 100" />
                <geom type="mesh" contype="0" conaffinity="0" group="1" density="0"
                  rgba="0.69804 0.69804 0.69804 1" mesh="link5" />
                <geom type="mesh" rgba="0.69804 0.69804 0.69804 1" mesh="link5" />
                <body name="link6" pos="0.02895 0 0.0865" quat="-3.67321e-06 -1 0 0">
                  <inertial pos="0.05181 1.84576e-05 -8.10076e-06"
                    quat="0.00846926 0.71019 0.00799092 0.703914" mass="0.570486"
                    diaginertia="0.000796424 0.000539346 0.000458732" />
                  <joint name="joint6" pos="0 0 0" axis="1 0 0" range="-10 10"
                    actuatorfrcrange="-100 100" />
                  <geom type="mesh" contype="0" conaffinity="0" group="1" density="0"
                    rgba="0.89804 0.91765 0.92941 1" mesh="link6" />
                  <geom type="mesh" rgba="0.89804 0.91765 0.92941 1" mesh="link6" />
                  <geom pos="0.08657 0.024896 -0.0002436" quat="1 0 0 0" type="mesh" contype="0"
                    conaffinity="0" group="1" density="0" rgba="1 1 1 1" mesh="link7" />
                  <geom pos="0.08657 0.024896 -0.0002436" quat="1 0 0 0" type="mesh" rgba="1 1 1 1"
                    mesh="link7" />
                  <geom pos="0.08657 -0.0249 -0.00024366" quat="1 0 0 0" type="mesh" contype="0"
                    conaffinity="0" group="1" density="0" rgba="1 1 1 1" mesh="link8" />
                  <geom pos="0.08657 -0.0249 -0.00024366" quat="1 0 0 0" type="mesh" rgba="1 1 1 1"
                    mesh="link8" />
                </body>
              </body>
            </body>
          </body>
        </body>
      </body>
    </body>
  </worldbody>

  <actuator>
    <motor name="FL_abd_joint" joint="FL_abd_joint" gear="1" ctrllimited="true"
      ctrlrange="-180 180" />
    <motor name="FL_hip_joint" joint="FL_hip_joint" gear="1" ctrllimited="true"
      ctrlrange="-180 180" />
    <motor name="FL_knee_joint" joint="FL_knee_joint" gear="1" ctrllimited="true"
      ctrlrange="-180 180" />

    <motor name="FR_abd_joint" joint="FR_abd_joint" gear="1" ctrllimited="true"
      ctrlrange="-180 180" />
    <motor name="FR_hip_joint" joint="FR_hip_joint" gear="1" ctrllimited="true"
      ctrlrange="-180 180" />
    <motor name="FR_knee_joint" joint="FR_knee_joint" gear="1" ctrllimited="true"
      ctrlrange="-180 180" />

    <motor name="HL_abd_joint" joint="HL_abd_joint" gear="1" ctrllimited="true"
      ctrlrange="-180 180" />
    <motor name="HL_hip_joint" joint="HL_hip_joint" gear="1" ctrllimited="true"
      ctrlrange="-180 180" />
    <motor name="HL_knee_joint" joint="HL_knee_joint" gear="1" ctrllimited="true"
      ctrlrange="-180 180" />

    <motor name="HR_abd_joint" joint="HR_abd_joint" gear="1" ctrllimited="true"
      ctrlrange="-180 180" />
    <motor name="HR_hip_joint" joint="HR_hip_joint" gear="1" ctrllimited="true"
      ctrlrange="-180 180" />
    <motor name="HR_knee_joint" joint="HR_knee_joint" gear="1" ctrllimited="true"
      ctrlrange="-180 180" />

    <motor name="joint1" joint="joint1" gear="1" ctrllimited="true" ctrlrange="-100 100" />
    <motor name="joint2" joint="joint2" gear="1" ctrllimited="true" ctrlrange="-100 100" />
    <motor name="joint3" joint="joint3" gear="1" ctrllimited="true" ctrlrange="-100 100" />
    <motor name="joint4" joint="joint4" gear="1" ctrllimited="true" ctrlrange="-100 100" />
    <motor name="joint5" joint="joint5" gear="1" ctrllimited="true" ctrlrange="-100 100" />
    <motor name="joint6" joint="joint6" gear="1" ctrllimited="true" ctrlrange="-100 100" />
  </actuator>
  <sensor>
    <framequat name="imu_quat" objtype="site" objname="site_imu" />
    <accelerometer name="imu_acc" site="site_imu" />
    <gyro name="imu_gyro" site="site_imu" />
  </sensor>
  <contact>
    <exclude body1="base_link" body2="FR_abd_link" />
    <exclude body1="base_link" body2="HR_abd_link" />
    <exclude body1="base_link" body2="FL_abd_link" />
    <exclude body1="base_link" body2="HL_abd_link" />
    <exclude body1="base_link" body2="FR_hip_link" />
    <exclude body1="base_link" body2="HR_hip_link" />
    <exclude body1="base_link" body2="FL_hip_link" />
    <exclude body1="base_link" body2="HL_hip_link" />
  </contact>

  <keyframe>
    <key name="stand"
      qpos="0 0 0.38 1 0 0 0 0 0.72 -1.44 0 0.72 -1.44 0 0.72 -1.44 0 0.72 -1.44 0 0 0 0 0 0" />
    <key name="down"
      qpos="0 0 0.15 1 0 0 0 0.5 1.05 -2.46 -0.5 1.05 -2.46 0.5 1.05 -2.46 -0.5 1.05 -2.46 0 0 0 0 0 0" />
  </keyframe>
</mujoco>
